Workbook

Sheet README
A1: Fantasy Cricket MVP Workbook (Google Sheets-friendly template)
A3: Workflow
A4: Fill Rules, Players and Matches.
A5: Add each match pool in MatchSquad.
A6: Create one row per fantasy team in Entries.
A7: Add 11 picks per entry in FantasySelections.
A8: Enter ball-by-ball events live in BallByBall.
A9: If you want maiden-over scoring, fill OverSummary.
A10: PlayerPoints, Validation and Leaderboard update automatically.
A13: Notes
A14: Use PlayerID everywhere. One row per selected player is easier than 11 player columns.
A15: Capacities are modest in this template so the workbook stays light. In Google Sheets, duplicate the formulas further down if needed.
... A17: Credits are intentionally blank because official squad pages do not publish fantasy credit values.

Sheet Rules
A1: Contest Controls
A2: Max players per fantasy team | B2: 11 | D2: Edit only blue cells in column B.
A3: Min WK | B3: 1
A4: Min BAT | B4: 1
A5: Min AR | B5: 1
A6: Min BWL | B6: 1
A7: Max from one real team | B7: 7
A8: Salary cap | B8: 100
A9: Captain multiplier | B9: 2
A10: Vice-captain multiplier | B10: 1.5
A12: Scoring Rules
A13: Bat run | B13: 1
A14: Four bonus | B14: 1
A15: Six bonus | B15: 2
A16: 30 run bonus | B16: 4
A17: 50 run bonus | B17: 10
A18: 100 run bonus | B18: 20
A19: Wicket | B19: 25
A20: 3 wicket bonus | B20: 10
A21: 4 wicket bonus | B21: 20
A22: Maiden over | B22: 12
A23: Catch | B23: 8
A24: Stumping | B24: 12
... A27: Duck penalty | B27: -2

Sheet Players
A1: PlayerID | B1: PlayerName | C1: Role | D1: RealTeam | E1: Credits | F1: Active? (1/0) | G1: Notes
A2: P001 | B2: Ruturaj Gaikwad | C2: BAT | D2: CSK | F2: 1 | G2: https://www.iplt20.com/teams/chennai-super-kings
A3: P002 | B3: MS Dhoni | C3: WK | D3: CSK | F3: 1 | G3: https://www.iplt20.com/teams/chennai-super-kings
A4: P003 | B4: Sanju Samson | C4: WK | D4: CSK | F4: 1 | G4: https://www.iplt20.com/teams/chennai-super-kings
A5: P004 | B5: Dewald Brevis | C5: BAT | D5: CSK | F5: 1 | G5: https://www.iplt20.com/teams/chennai-super-kings
A6: P005 | B6: Ayush Mhatre | C6: BAT | D6: CSK | F6: 1 | G6: https://www.iplt20.com/teams/chennai-super-kings
A7: P006 | B7: Kartik Sharma | C7: WK | D7: CSK | F7: 1 | G7: https://www.iplt20.com/teams/chennai-super-kings
A8: P007 | B8: Sarfaraz Khan | C8: BAT | D8: CSK | F8: 1 | G8: https://www.iplt20.com/teams/chennai-super-kings
A9: P008 | B9: Urvil Patel | C9: WK | D9: CSK | F9: 1 | G9: https://www.iplt20.com/teams/chennai-super-kings
A10: P009 | B10: Jamie Overton | C10: AR | D10: CSK | F10: 1 | G10: https://www.iplt20.com/teams/chennai-super-kings
A11: P010 | B11: Ramakrishna Ghosh | C11: AR | D11: CSK | F11: 1 | G11: https://www.iplt20.com/teams/chennai-super-kings
A12: P011 | B12: Prashant Veer | C12: AR | D12: CSK | F12: 1 | G12: https://www.iplt20.com/teams/chennai-super-kings
A13: P012 | B13: Matthew William Short | C13: AR | D13: CSK | F13: 1 | G13: https://www.iplt20.com/teams/chennai-super-kings
... A251: P250 | B251: Shivam Mavi | C251: BWL | D251: SRH | F251: 1 | G251: https://www.iplt20.com/teams/sunrisers-hyderabad

Sheet Matches
A1: MatchID | B1: MatchName | C1: StartTime | D1: TeamA | E1: TeamB | F1: Status | G1: LockTime | H1: Notes
A2: M001 | B2: Royal Challengers Bengaluru vs Sunrisers Hyderabad | C2: 2026-03-28 19:30 | D2: RCB | E2: SRH | F2: Complete | G2: 2026-03-28 19:00 | H2: Venue: Bengaluru; Source: https://www.iplt20.com/news/4249/tata-indian-premier-league-ipl-2026-schedule-announced-for-first-two-weeks
A3: M002 | B3: Mumbai Indians vs Kolkata Knight Riders | C3: 2026-03-29 19:30 | D3: MI | E3: KKR | F3: Complete | G3: 2026-03-29 19:00 | H3: Venue: Mumbai; Source: https://www.iplt20.com/news/4249/tata-indian-premier-league-ipl-2026-schedule-announced-for-first-two-weeks
A4: M003 | B4: Rajasthan Royals vs Chennai Super Kings | C4: 2026-03-30 19:30 | D4: RR | E4: CSK | F4: Complete | G4: 2026-03-30 19:00 | H4: Venue: Guwahati; Source: https://www.iplt20.com/news/4249/tata-indian-premier-league-ipl-2026-schedule-announced-for-first-two-weeks
A5: M004 | B5: Punjab Kings vs Gujarat Titans | C5: 2026-03-31 19:30 | D5: PBKS | E5: GT | F5: Complete | G5: 2026-03-31 19:00 | H5: Venue: New Chandigarh; Source: https://www.iplt20.com/news/4249/tata-indian-premier-league-ipl-2026-schedule-announced-for-first-two-weeks
A6: M005 | B6: Lucknow Super Giants vs Delhi Capitals | C6: 2026-04-01 19:30 | D6: LSG | E6: DC | F6: Complete | G6: 2026-04-01 19:00 | H6: Venue: Lucknow; Source: https://www.iplt20.com/news/4249/tata-indian-premier-league-ipl-2026-schedule-announced-for-first-two-weeks
A7: M006 | B7: Kolkata Knight Riders vs Sunrisers Hyderabad | C7: 2026-04-02 19:30 | D7: KKR | E7: SRH | F7: Complete | G7: 2026-04-02 19:00 | H7: Venue: Kolkata; Source: https://www.iplt20.com/news/4249/tata-indian-premier-league-ipl-2026-schedule-announced-for-first-two-weeks
A8: M007 | B8: Chennai Super Kings vs Punjab Kings | C8: 2026-04-03 19:30 | D8: CSK | E8: PBKS | F8: Complete | G8: 2026-04-03 19:00 | H8: Venue: Chennai; Source: https://www.iplt20.com/news/4249/tata-indian-premier-league-ipl-2026-schedule-announced-for-first-two-weeks
A9: M008 | B9: Delhi Capitals vs Mumbai Indians | C9: 2026-04-04 15:30 | D9: DC | E9: MI | F9: Complete | G9: 2026-04-04 15:00 | H9: Venue: Delhi; Source: https://www.iplt20.com/news/4249/tata-indian-premier-league-ipl-2026-schedule-announced-for-first-two-weeks
A10: M009 | B10: Gujarat Titans vs Rajasthan Royals | C10: 2026-04-04 19:30 | D10: GT | E10: RR | F10: Complete | G10: 2026-04-04 19:00 | H10: Venue: Ahmedabad; Source: https://www.iplt20.com/news/4249/tata-indian-premier-league-ipl-2026-schedule-announced-for-first-two-weeks
A11: M010 | B11: Sunrisers Hyderabad vs Lucknow Super Giants | C11: 2026-04-05 15:30 | D11: SRH | E11: LSG | F11: Complete | G11: 2026-04-05 15:00 | H11: Venue: Hyderabad; Source: https://www.iplt20.com/news/4249/tata-indian-premier-league-ipl-2026-schedule-announced-for-first-two-weeks
A12: M011 | B12: Royal Challengers Bengaluru vs Chennai Super Kings | C12: 2026-04-05 19:30 | D12: RCB | E12: CSK | F12: Complete | G12: 2026-04-05 19:00 | H12: Venue: Bengaluru; Source: https://www.iplt20.com/news/4249/tata-indian-premier-league-ipl-2026-schedule-announced-for-first-two-weeks
... A71: M070 | B71: Kolkata Knight Riders vs Delhi Capitals | C71: 2026-05-24 19:30 | D71: KKR | E71: DC | F71: Open | G71: 2026-05-24 19:00 | H71: Venue: Kolkata; Source: https://www.iplt20.com/news/4253/tata-indian-premier-league-2026-updated-schedule-announced

Sheet MatchSquad
A1: MatchID | B1: PlayerID | C1: PlayerName | D1: Role | E1: RealTeam | F1: Credits | G1: InStartingXI (1/0) | H1: Notes
A2: M001 | B2: P201 | C2: =IFERROR(VLOOKUP(B2,Players!$A$2:$E$251,2,FALSE),"") -> Rajat Patidar | D2: =IFERROR(VLOOKUP(B2,Players!$A$2:$E$251,3,FALSE),"") -> BAT | E2: =IFERROR(VLOOKUP(B2,Players!$A$2:$E$251,4,FALSE),"") -> RCB | F2: =IFERROR(VLOOKUP(B2,Players!$A$2:$E$251,5,FALSE),"") -> 0 | H2: Source squad: https://www.iplt20.com/teams/royal-challengers-bengaluru
A3: M001 | B3: P202 | C3: =IFERROR(VLOOKUP(B3,Players!$A$2:$E$251,2,FALSE),"") -> Devdutt Padikkal | D3: =IFERROR(VLOOKUP(B3,Players!$A$2:$E$251,3,FALSE),"") -> BAT | E3: =IFERROR(VLOOKUP(B3,Players!$A$2:$E$251,4,FALSE),"") -> RCB | F3: =IFERROR(VLOOKUP(B3,Players!$A$2:$E$251,5,FALSE),"") -> 0 | H3: Source squad: https://www.iplt20.com/teams/royal-challengers-bengaluru
A4: M001 | B4: P203 | C4: =IFERROR(VLOOKUP(B4,Players!$A$2:$E$251,2,FALSE),"") -> Virat Kohli | D4: =IFERROR(VLOOKUP(B4,Players!$A$2:$E$251,3,FALSE),"") -> BAT | E4: =IFERROR(VLOOKUP(B4,Players!$A$2:$E$251,4,FALSE),"") -> RCB | F4: =IFERROR(VLOOKUP(B4,Players!$A$2:$E$251,5,FALSE),"") -> 0 | H4: Source squad: https://www.iplt20.com/teams/royal-challengers-bengaluru
A5: M001 | B5: P204 | C5: =IFERROR(VLOOKUP(B5,Players!$A$2:$E$251,2,FALSE),"") -> Phil Salt | D5: =IFERROR(VLOOKUP(B5,Players!$A$2:$E$251,3,FALSE),"") -> WK | E5: =IFERROR(VLOOKUP(B5,Players!$A$2:$E$251,4,FALSE),"") -> RCB | F5: =IFERROR(VLOOKUP(B5,Players!$A$2:$E$251,5,FALSE),"") -> 0 | H5: Source squad: https://www.iplt20.com/teams/royal-challengers-bengaluru
A6: M001 | B6: P205 | C6: =IFERROR(VLOOKUP(B6,Players!$A$2:$E$251,2,FALSE),"") -> Jitesh Sharma | D6: =IFERROR(VLOOKUP(B6,Players!$A$2:$E$251,3,FALSE),"") -> WK | E6: =IFERROR(VLOOKUP(B6,Players!$A$2:$E$251,4,FALSE),"") -> RCB | F6: =IFERROR(VLOOKUP(B6,Players!$A$2:$E$251,5,FALSE),"") -> 0 | H6: Source squad: https://www.iplt20.com/teams/royal-challengers-bengaluru
A7: M001 | B7: P206 | C7: =IFERROR(VLOOKUP(B7,Players!$A$2:$E$251,2,FALSE),"") -> Jordan Cox | D7: =IFERROR(VLOOKUP(B7,Players!$A$2:$E$251,3,FALSE),"") -> WK | E7: =IFERROR(VLOOKUP(B7,Players!$A$2:$E$251,4,FALSE),"") -> RCB | F7: =IFERROR(VLOOKUP(B7,Players!$A$2:$E$251,5,FALSE),"") -> 0 | H7: Source squad: https://www.iplt20.com/teams/royal-challengers-bengaluru
A8: M001 | B8: P207 | C8: =IFERROR(VLOOKUP(B8,Players!$A$2:$E$251,2,FALSE),"") -> Krunal Pandya | D8: =IFERROR(VLOOKUP(B8,Players!$A$2:$E$251,3,FALSE),"") -> AR | E8: =IFERROR(VLOOKUP(B8,Players!$A$2:$E$251,4,FALSE),"") -> RCB | F8: =IFERROR(VLOOKUP(B8,Players!$A$2:$E$251,5,FALSE),"") -> 0 | H8: Source squad: https://www.iplt20.com/teams/royal-challengers-bengaluru
A9: M001 | B9: P208 | C9: =IFERROR(VLOOKUP(B9,Players!$A$2:$E$251,2,FALSE),"") -> Swapnil Singh | D9: =IFERROR(VLOOKUP(B9,Players!$A$2:$E$251,3,FALSE),"") -> AR | E9: =IFERROR(VLOOKUP(B9,Players!$A$2:$E$251,4,FALSE),"") -> RCB | F9: =IFERROR(VLOOKUP(B9,Players!$A$2:$E$251,5,FALSE),"") -> 0 | H9: Source squad: https://www.iplt20.com/teams/royal-challengers-bengaluru
A10: M001 | B10: P209 | C10: =IFERROR(VLOOKUP(B10,Players!$A$2:$E$251,2,FALSE),"") -> Tim David | D10: =IFERROR(VLOOKUP(B10,Players!$A$2:$E$251,3,FALSE),"") -> AR | E10: =IFERROR(VLOOKUP(B10,Players!$A$2:$E$251,4,FALSE),"") -> RCB | F10: =IFERROR(VLOOKUP(B10,Players!$A$2:$E$251,5,FALSE),"") -> 0 | H10: Source squad: https://www.iplt20.com/teams/royal-challengers-bengaluru
A11: M001 | B11: P210 | C11: =IFERROR(VLOOKUP(B11,Players!$A$2:$E$251,2,FALSE),"") -> Romario Shepherd | D11: =IFERROR(VLOOKUP(B11,Players!$A$2:$E$251,3,FALSE),"") -> AR | E11: =IFERROR(VLOOKUP(B11,Players!$A$2:$E$251,4,FALSE),"") -> RCB | F11: =IFERROR(VLOOKUP(B11,Players!$A$2:$E$251,5,FALSE),"") -> 0 | H11: Source squad: https://www.iplt20.com/teams/royal-challengers-bengaluru
A12: M001 | B12: P211 | C12: =IFERROR(VLOOKUP(B12,Players!$A$2:$E$251,2,FALSE),"") -> Jacob Bethell | D12: =IFERROR(VLOOKUP(B12,Players!$A$2:$E$251,3,FALSE),"") -> AR | E12: =IFERROR(VLOOKUP(B12,Players!$A$2:$E$251,4,FALSE),"") -> RCB | F12: =IFERROR(VLOOKUP(B12,Players!$A$2:$E$251,5,FALSE),"") -> 0 | H12: Source squad: https://www.iplt20.com/teams/royal-challengers-bengaluru
A13: M001 | B13: P212 | C13: =IFERROR(VLOOKUP(B13,Players!$A$2:$E$251,2,FALSE),"") -> Venkatesh Iyer | D13: =IFERROR(VLOOKUP(B13,Players!$A$2:$E$251,3,FALSE),"") -> AR | E13: =IFERROR(VLOOKUP(B13,Players!$A$2:$E$251,4,FALSE),"") -> RCB | F13: =IFERROR(VLOOKUP(B13,Players!$A$2:$E$251,5,FALSE),"") -> 0 | H13: Source squad: https://www.iplt20.com/teams/royal-challengers-bengaluru
... A3501: M070 | B3501: P050 | C3501: =IFERROR(VLOOKUP(B3501,Players!$A$2:$E$251,2,FALSE),"") -> Kuldeep Yadav | D3501: =IFERROR(VLOOKUP(B3501,Players!$A$2:$E$251,3,FALSE),"") -> BWL | E3501: =IFERROR(VLOOKUP(B3501,Players!$A$2:$E$251,4,FALSE),"") -> DC | F3501: =IFERROR(VLOOKUP(B3501,Players!$A$2:$E$251,5,FALSE),"") -> 0 | H3501: Source squad: https://www.iplt20.com/teams/delhi-capitals

Sheet Entries
A1: EntryID | B1: MatchID | C1: UserName | D1: SubmittedAt | E1: Notes

Sheet FantasySelections
A1: EntryID | B1: MatchID | C1: UserName | D1: PickNo | E1: PlayerID | F1: PlayerName | G1: Role | H1: RealTeam | I1: Credits | J1: IsCaptain (1/0) | K1: IsViceCaptain (1/0) | L1: ValidPlayerForMatch | M1: BasePoints | N1: Multiplier | O1: FinalPoints | P1: UniquePickFlag
B2: =IFERROR(VLOOKUP(A2,Entries!$A$2:$C$31,2,FALSE),"") | C2: =IFERROR(VLOOKUP(A2,Entries!$A$2:$C$31,3,FALSE),"") | F2: =IFERROR(VLOOKUP(E2,Players!$A$2:$E$251,2,FALSE),"") | G2: =IFERROR(VLOOKUP(E2,Players!$A$2:$E$251,3,FALSE),"") | H2: =IFERROR(VLOOKUP(E2,Players!$A$2:$E$251,4,FALSE),"") | I2: =IFERROR(VLOOKUP(E2,Players!$A$2:$E$251,5,FALSE),0) -> 0 | L2: =IF(A2="","",IF(COUNTIFS(MatchSquad!$A$2:$A$3501,B2,MatchSquad!$B$2:$B$3501,E2)>0,1,0)) | M2: =IF(A2="","",SUMIFS(PlayerPoints!$U$2:$U$3501,PlayerPoints!$A$2:$A$3501,B2,PlayerPoints!$B$2:$B$3501,E2)) | N2: =IF(J2=1,Rules!$B$9,IF(K2=1,Rules!$B$10,1)) -> 1 | O2: =IF(A2="","",M2*N2) | P2: =IF(AND(A2<>"",E2<>""),IF(COUNTIFS($A$2:A2,A2,$E$2:E2,E2)=1,1,0),0) -> 0
B3: =IFERROR(VLOOKUP(A3,Entries!$A$2:$C$31,2,FALSE),"") | C3: =IFERROR(VLOOKUP(A3,Entries!$A$2:$C$31,3,FALSE),"") | F3: =IFERROR(VLOOKUP(E3,Players!$A$2:$E$251,2,FALSE),"") | G3: =IFERROR(VLOOKUP(E3,Players!$A$2:$E$251,3,FALSE),"") | H3: =IFERROR(VLOOKUP(E3,Players!$A$2:$E$251,4,FALSE),"") | I3: =IFERROR(VLOOKUP(E3,Players!$A$2:$E$251,5,FALSE),0) -> 0 | L3: =IF(A3="","",IF(COUNTIFS(MatchSquad!$A$2:$A$3501,B3,MatchSquad!$B$2:$B$3501,E3)>0,1,0)) | M3: =IF(A3="","",SUMIFS(PlayerPoints!$U$2:$U$3501,PlayerPoints!$A$2:$A$3501,B3,PlayerPoints!$B$2:$B$3501,E3)) | N3: =IF(J3=1,Rules!$B$9,IF(K3=1,Rules!$B$10,1)) -> 1 | O3: =IF(A3="","",M3*N3) | P3: =IF(AND(A3<>"",E3<>""),IF(COUNTIFS($A$2:A3,A3,$E$2:E3,E3)=1,1,0),0) -> 0
B4: =IFERROR(VLOOKUP(A4,Entries!$A$2:$C$31,2,FALSE),"") | C4: =IFERROR(VLOOKUP(A4,Entries!$A$2:$C$31,3,FALSE),"") | F4: =IFERROR(VLOOKUP(E4,Players!$A$2:$E$251,2,FALSE),"") | G4: =IFERROR(VLOOKUP(E4,Players!$A$2:$E$251,3,FALSE),"") | H4: =IFERROR(VLOOKUP(E4,Players!$A$2:$E$251,4,FALSE),"") | I4: =IFERROR(VLOOKUP(E4,Players!$A$2:$E$251,5,FALSE),0) -> 0 | L4: =IF(A4="","",IF(COUNTIFS(MatchSquad!$A$2:$A$3501,B4,MatchSquad!$B$2:$B$3501,E4)>0,1,0)) | M4: =IF(A4="","",SUMIFS(PlayerPoints!$U$2:$U$3501,PlayerPoints!$A$2:$A$3501,B4,PlayerPoints!$B$2:$B$3501,E4)) | N4: =IF(J4=1,Rules!$B$9,IF(K4=1,Rules!$B$10,1)) -> 1 | O4: =IF(A4="","",M4*N4) | P4: =IF(AND(A4<>"",E4<>""),IF(COUNTIFS($A$2:A4,A4,$E$2:E4,E4)=1,1,0),0) -> 0
B5: =IFERROR(VLOOKUP(A5,Entries!$A$2:$C$31,2,FALSE),"") | C5: =IFERROR(VLOOKUP(A5,Entries!$A$2:$C$31,3,FALSE),"") | F5: =IFERROR(VLOOKUP(E5,Players!$A$2:$E$251,2,FALSE),"") | G5: =IFERROR(VLOOKUP(E5,Players!$A$2:$E$251,3,FALSE),"") | H5: =IFERROR(VLOOKUP(E5,Players!$A$2:$E$251,4,FALSE),"") | I5: =IFERROR(VLOOKUP(E5,Players!$A$2:$E$251,5,FALSE),0) -> 0 | L5: =IF(A5="","",IF(COUNTIFS(MatchSquad!$A$2:$A$3501,B5,MatchSquad!$B$2:$B$3501,E5)>0,1,0)) | M5: =IF(A5="","",SUMIFS(PlayerPoints!$U$2:$U$3501,PlayerPoints!$A$2:$A$3501,B5,PlayerPoints!$B$2:$B$3501,E5)) | N5: =IF(J5=1,Rules!$B$9,IF(K5=1,Rules!$B$10,1)) -> 1 | O5: =IF(A5="","",M5*N5) | P5: =IF(AND(A5<>"",E5<>""),IF(COUNTIFS($A$2:A5,A5,$E$2:E5,E5)=1,1,0),0) -> 0
B6: =IFERROR(VLOOKUP(A6,Entries!$A$2:$C$31,2,FALSE),"") | C6: =IFERROR(VLOOKUP(A6,Entries!$A$2:$C$31,3,FALSE),"") | F6: =IFERROR(VLOOKUP(E6,Players!$A$2:$E$251,2,FALSE),"") | G6: =IFERROR(VLOOKUP(E6,Players!$A$2:$E$251,3,FALSE),"") | H6: =IFERROR(VLOOKUP(E6,Players!$A$2:$E$251,4,FALSE),"") | I6: =IFERROR(VLOOKUP(E6,Players!$A$2:$E$251,5,FALSE),0) -> 0 | L6: =IF(A6="","",IF(COUNTIFS(MatchSquad!$A$2:$A$3501,B6,MatchSquad!$B$2:$B$3501,E6)>0,1,0)) | M6: =IF(A6="","",SUMIFS(PlayerPoints!$U$2:$U$3501,PlayerPoints!$A$2:$A$3501,B6,PlayerPoints!$B$2:$B$3501,E6)) | N6: =IF(J6=1,Rules!$B$9,IF(K6=1,Rules!$B$10,1)) -> 1 | O6: =IF(A6="","",M6*N6) | P6: =IF(AND(A6<>"",E6<>""),IF(COUNTIFS($A$2:A6,A6,$E$2:E6,E6)=1,1,0),0) -> 0
B7: =IFERROR(VLOOKUP(A7,Entries!$A$2:$C$31,2,FALSE),"") | C7: =IFERROR(VLOOKUP(A7,Entries!$A$2:$C$31,3,FALSE),"") | F7: =IFERROR(VLOOKUP(E7,Players!$A$2:$E$251,2,FALSE),"") | G7: =IFERROR(VLOOKUP(E7,Players!$A$2:$E$251,3,FALSE),"") | H7: =IFERROR(VLOOKUP(E7,Players!$A$2:$E$251,4,FALSE),"") | I7: =IFERROR(VLOOKUP(E7,Players!$A$2:$E$251,5,FALSE),0) -> 0 | L7: =IF(A7="","",IF(COUNTIFS(MatchSquad!$A$2:$A$3501,B7,MatchSquad!$B$2:$B$3501,E7)>0,1,0)) | M7: =IF(A7="","",SUMIFS(PlayerPoints!$U$2:$U$3501,PlayerPoints!$A$2:$A$3501,B7,PlayerPoints!$B$2:$B$3501,E7)) | N7: =IF(J7=1,Rules!$B$9,IF(K7=1,Rules!$B$10,1)) -> 1 | O7: =IF(A7="","",M7*N7) | P7: =IF(AND(A7<>"",E7<>""),IF(COUNTIFS($A$2:A7,A7,$E$2:E7,E7)=1,1,0),0) -> 0
B8: =IFERROR(VLOOKUP(A8,Entries!$A$2:$C$31,2,FALSE),"") | C8: =IFERROR(VLOOKUP(A8,Entries!$A$2:$C$31,3,FALSE),"") | F8: =IFERROR(VLOOKUP(E8,Players!$A$2:$E$251,2,FALSE),"") | G8: =IFERROR(VLOOKUP(E8,Players!$A$2:$E$251,3,FALSE),"") | H8: =IFERROR(VLOOKUP(E8,Players!$A$2:$E$251,4,FALSE),"") | I8: =IFERROR(VLOOKUP(E8,Players!$A$2:$E$251,5,FALSE),0) -> 0 | L8: =IF(A8="","",IF(COUNTIFS(MatchSquad!$A$2:$A$3501,B8,MatchSquad!$B$2:$B$3501,E8)>0,1,0)) | M8: =IF(A8="","",SUMIFS(PlayerPoints!$U$2:$U$3501,PlayerPoints!$A$2:$A$3501,B8,PlayerPoints!$B$2:$B$3501,E8)) | N8: =IF(J8=1,Rules!$B$9,IF(K8=1,Rules!$B$10,1)) -> 1 | O8: =IF(A8="","",M8*N8) | P8: =IF(AND(A8<>"",E8<>""),IF(COUNTIFS($A$2:A8,A8,$E$2:E8,E8)=1,1,0),0) -> 0
B9: =IFERROR(VLOOKUP(A9,Entries!$A$2:$C$31,2,FALSE),"") | C9: =IFERROR(VLOOKUP(A9,Entries!$A$2:$C$31,3,FALSE),"") | F9: =IFERROR(VLOOKUP(E9,Players!$A$2:$E$251,2,FALSE),"") | G9: =IFERROR(VLOOKUP(E9,Players!$A$2:$E$251,3,FALSE),"") | H9: =IFERROR(VLOOKUP(E9,Players!$A$2:$E$251,4,FALSE),"") | I9: =IFERROR(VLOOKUP(E9,Players!$A$2:$E$251,5,FALSE),0) -> 0 | L9: =IF(A9="","",IF(COUNTIFS(MatchSquad!$A$2:$A$3501,B9,MatchSquad!$B$2:$B$3501,E9)>0,1,0)) | M9: =IF(A9="","",SUMIFS(PlayerPoints!$U$2:$U$3501,PlayerPoints!$A$2:$A$3501,B9,PlayerPoints!$B$2:$B$3501,E9)) | N9: =IF(J9=1,Rules!$B$9,IF(K9=1,Rules!$B$10,1)) -> 1 | O9: =IF(A9="","",M9*N9) | P9: =IF(AND(A9<>"",E9<>""),IF(COUNTIFS($A$2:A9,A9,$E$2:E9,E9)=1,1,0),0) -> 0
B10: =IFERROR(VLOOKUP(A10,Entries!$A$2:$C$31,2,FALSE),"") | C10: =IFERROR(VLOOKUP(A10,Entries!$A$2:$C$31,3,FALSE),"") | F10: =IFERROR(VLOOKUP(E10,Players!$A$2:$E$251,2,FALSE),"") | G10: =IFERROR(VLOOKUP(E10,Players!$A$2:$E$251,3,FALSE),"") | H10: =IFERROR(VLOOKUP(E10,Players!$A$2:$E$251,4,FALSE),"") | I10: =IFERROR(VLOOKUP(E10,Players!$A$2:$E$251,5,FALSE),0) -> 0 | L10: =IF(A10="","",IF(COUNTIFS(MatchSquad!$A$2:$A$3501,B10,MatchSquad!$B$2:$B$3501,E10)>0,1,0)) | M10: =IF(A10="","",SUMIFS(PlayerPoints!$U$2:$U$3501,PlayerPoints!$A$2:$A$3501,B10,PlayerPoints!$B$2:$B$3501,E10)) | N10: =IF(J10=1,Rules!$B$9,IF(K10=1,Rules!$B$10,1)) -> 1 | O10: =IF(A10="","",M10*N10) | P10: =IF(AND(A10<>"",E10<>""),IF(COUNTIFS($A$2:A10,A10,$E$2:E10,E10)=1,1,0),0) -> 0
B11: =IFERROR(VLOOKUP(A11,Entries!$A$2:$C$31,2,FALSE),"") | C11: =IFERROR(VLOOKUP(A11,Entries!$A$2:$C$31,3,FALSE),"") | F11: =IFERROR(VLOOKUP(E11,Players!$A$2:$E$251,2,FALSE),"") | G11: =IFERROR(VLOOKUP(E11,Players!$A$2:$E$251,3,FALSE),"") | H11: =IFERROR(VLOOKUP(E11,Players!$A$2:$E$251,4,FALSE),"") | I11: =IFERROR(VLOOKUP(E11,Players!$A$2:$E$251,5,FALSE),0) -> 0 | L11: =IF(A11="","",IF(COUNTIFS(MatchSquad!$A$2:$A$3501,B11,MatchSquad!$B$2:$B$3501,E11)>0,1,0)) | M11: =IF(A11="","",SUMIFS(PlayerPoints!$U$2:$U$3501,PlayerPoints!$A$2:$A$3501,B11,PlayerPoints!$B$2:$B$3501,E11)) | N11: =IF(J11=1,Rules!$B$9,IF(K11=1,Rules!$B$10,1)) -> 1 | O11: =IF(A11="","",M11*N11) | P11: =IF(AND(A11<>"",E11<>""),IF(COUNTIFS($A$2:A11,A11,$E$2:E11,E11)=1,1,0),0) -> 0
B12: =IFERROR(VLOOKUP(A12,Entries!$A$2:$C$31,2,FALSE),"") | C12: =IFERROR(VLOOKUP(A12,Entries!$A$2:$C$31,3,FALSE),"") | F12: =IFERROR(VLOOKUP(E12,Players!$A$2:$E$251,2,FALSE),"") | G12: =IFERROR(VLOOKUP(E12,Players!$A$2:$E$251,3,FALSE),"") | H12: =IFERROR(VLOOKUP(E12,Players!$A$2:$E$251,4,FALSE),"") | I12: =IFERROR(VLOOKUP(E12,Players!$A$2:$E$251,5,FALSE),0) -> 0 | L12: =IF(A12="","",IF(COUNTIFS(MatchSquad!$A$2:$A$3501,B12,MatchSquad!$B$2:$B$3501,E12)>0,1,0)) | M12: =IF(A12="","",SUMIFS(PlayerPoints!$U$2:$U$3501,PlayerPoints!$A$2:$A$3501,B12,PlayerPoints!$B$2:$B$3501,E12)) | N12: =IF(J12=1,Rules!$B$9,IF(K12=1,Rules!$B$10,1)) -> 1 | O12: =IF(A12="","",M12*N12) | P12: =IF(AND(A12<>"",E12<>""),IF(COUNTIFS($A$2:A12,A12,$E$2:E12,E12)=1,1,0),0) -> 0
B13: =IFERROR(VLOOKUP(A13,Entries!$A$2:$C$31,2,FALSE),"") | C13: =IFERROR(VLOOKUP(A13,Entries!$A$2:$C$31,3,FALSE),"") | F13: =IFERROR(VLOOKUP(E13,Players!$A$2:$E$251,2,FALSE),"") | G13: =IFERROR(VLOOKUP(E13,Players!$A$2:$E$251,3,FALSE),"") | H13: =IFERROR(VLOOKUP(E13,Players!$A$2:$E$251,4,FALSE),"") | I13: =IFERROR(VLOOKUP(E13,Players!$A$2:$E$251,5,FALSE),0) -> 0 | L13: =IF(A13="","",IF(COUNTIFS(MatchSquad!$A$2:$A$3501,B13,MatchSquad!$B$2:$B$3501,E13)>0,1,0)) | M13: =IF(A13="","",SUMIFS(PlayerPoints!$U$2:$U$3501,PlayerPoints!$A$2:$A$3501,B13,PlayerPoints!$B$2:$B$3501,E13)) | N13: =IF(J13=1,Rules!$B$9,IF(K13=1,Rules!$B$10,1)) -> 1 | O13: =IF(A13="","",M13*N13) | P13: =IF(AND(A13<>"",E13<>""),IF(COUNTIFS($A$2:A13,A13,$E$2:E13,E13)=1,1,0),0) -> 0
... B331: =IFERROR(VLOOKUP(A331,Entries!$A$2:$C$31,2,FALSE),"") | C331: =IFERROR(VLOOKUP(A331,Entries!$A$2:$C$31,3,FALSE),"") | F331: =IFERROR(VLOOKUP(E331,Players!$A$2:$E$251,2,FALSE),"") | G331: =IFERROR(VLOOKUP(E331,Players!$A$2:$E$251,3,FALSE),"") | H331: =IFERROR(VLOOKUP(E331,Players!$A$2:$E$251,4,FALSE),"") | I331: =IFERROR(VLOOKUP(E331,Players!$A$2:$E$251,5,FALSE),0) -> 0 | L331: =IF(A331="","",IF(COUNTIFS(MatchSquad!$A$2:$A$3501,B331,MatchSquad!$B$2:$B$3501,E331)>0,1,0)) | M331: =IF(A331="","",SUMIFS(PlayerPoints!$U$2:$U$3501,PlayerPoints!$A$2:$A$3501,B331,PlayerPoints!$B$2:$B$3501,E331)) | N331: =IF(J331=1,Rules!$B$9,IF(K331=1,Rules!$B$10,1)) -> 1 | O331: =IF(A331="","",M331*N331) | P331: =IF(AND(A331<>"",E331<>""),IF(COUNTIFS($A$2:A331,A331,$E$2:E331,E331)=1,1,0),0) -> 0

Sheet BallByBall
A1: EventID | B1: MatchID | C1: Innings | D1: Over | E1: Ball | F1: BatterID | G1: NonStrikerID | H1: BowlerID | I1: RunsBat | J1: Extras | K1: ExtraType | L1: IsLegalBall (1/0) | M1: WicketFlag (1/0) | N1: WicketType | O1: OutPlayerID | P1: FielderID | Q1: IsFour (1/0) | R1: IsSix (1/0) | S1: TotalRuns | T1: BowlerWicketFlag | U1: CatchFlag | V1: StumpingFlag | W1: RunOutDirectFlag | X1: RunOutAssistFlag | Y1: DotBallFlag | Z1: BowlerRunsConceded
S2: =IF(A2="","",I2+J2) | T2: =IF(A2="","",IF(AND(M2=1,N2<>"run out direct",N2<>"run out assist",N2<>"retired hurt",N2<>"obstructing field"),1,0)) | U2: =IF(A2="","",IF(AND(M2=1,N2="catch",P2<>""),1,0)) | V2: =IF(A2="","",IF(AND(M2=1,N2="stumping",P2<>""),1,0)) | W2: =IF(A2="","",IF(N2="run out direct",1,0)) | X2: =IF(A2="","",IF(N2="run out assist",1,0)) | Y2: =IF(A2="","",IF(AND(L2=1,S2=0),1,0)) | Z2: =IF(A2="","",I2+IF(OR(K2="wide",K2="no ball"),J2,0))
S3: =IF(A3="","",I3+J3) | T3: =IF(A3="","",IF(AND(M3=1,N3<>"run out direct",N3<>"run out assist",N3<>"retired hurt",N3<>"obstructing field"),1,0)) | U3: =IF(A3="","",IF(AND(M3=1,N3="catch",P3<>""),1,0)) | V3: =IF(A3="","",IF(AND(M3=1,N3="stumping",P3<>""),1,0)) | W3: =IF(A3="","",IF(N3="run out direct",1,0)) | X3: =IF(A3="","",IF(N3="run out assist",1,0)) | Y3: =IF(A3="","",IF(AND(L3=1,S3=0),1,0)) | Z3: =IF(A3="","",I3+IF(OR(K3="wide",K3="no ball"),J3,0))
S4: =IF(A4="","",I4+J4) | T4: =IF(A4="","",IF(AND(M4=1,N4<>"run out direct",N4<>"run out assist",N4<>"retired hurt",N4<>"obstructing field"),1,0)) | U4: =IF(A4="","",IF(AND(M4=1,N4="catch",P4<>""),1,0)) | V4: =IF(A4="","",IF(AND(M4=1,N4="stumping",P4<>""),1,0)) | W4: =IF(A4="","",IF(N4="run out direct",1,0)) | X4: =IF(A4="","",IF(N4="run out assist",1,0)) | Y4: =IF(A4="","",IF(AND(L4=1,S4=0),1,0)) | Z4: =IF(A4="","",I4+IF(OR(K4="wide",K4="no ball"),J4,0))
S5: =IF(A5="","",I5+J5) | T5: =IF(A5="","",IF(AND(M5=1,N5<>"run out direct",N5<>"run out assist",N5<>"retired hurt",N5<>"obstructing field"),1,0)) | U5: =IF(A5="","",IF(AND(M5=1,N5="catch",P5<>""),1,0)) | V5: =IF(A5="","",IF(AND(M5=1,N5="stumping",P5<>""),1,0)) | W5: =IF(A5="","",IF(N5="run out direct",1,0)) | X5: =IF(A5="","",IF(N5="run out assist",1,0)) | Y5: =IF(A5="","",IF(AND(L5=1,S5=0),1,0)) | Z5: =IF(A5="","",I5+IF(OR(K5="wide",K5="no ball"),J5,0))
S6: =IF(A6="","",I6+J6) | T6: =IF(A6="","",IF(AND(M6=1,N6<>"run out direct",N6<>"run out assist",N6<>"retired hurt",N6<>"obstructing field"),1,0)) | U6: =IF(A6="","",IF(AND(M6=1,N6="catch",P6<>""),1,0)) | V6: =IF(A6="","",IF(AND(M6=1,N6="stumping",P6<>""),1,0)) | W6: =IF(A6="","",IF(N6="run out direct",1,0)) | X6: =IF(A6="","",IF(N6="run out assist",1,0)) | Y6: =IF(A6="","",IF(AND(L6=1,S6=0),1,0)) | Z6: =IF(A6="","",I6+IF(OR(K6="wide",K6="no ball"),J6,0))
S7: =IF(A7="","",I7+J7) | T7: =IF(A7="","",IF(AND(M7=1,N7<>"run out direct",N7<>"run out assist",N7<>"retired hurt",N7<>"obstructing field"),1,0)) | U7: =IF(A7="","",IF(AND(M7=1,N7="catch",P7<>""),1,0)) | V7: =IF(A7="","",IF(AND(M7=1,N7="stumping",P7<>""),1,0)) | W7: =IF(A7="","",IF(N7="run out direct",1,0)) | X7: =IF(A7="","",IF(N7="run out assist",1,0)) | Y7: =IF(A7="","",IF(AND(L7=1,S7=0),1,0)) | Z7: =IF(A7="","",I7+IF(OR(K7="wide",K7="no ball"),J7,0))
S8: =IF(A8="","",I8+J8) | T8: =IF(A8="","",IF(AND(M8=1,N8<>"run out direct",N8<>"run out assist",N8<>"retired hurt",N8<>"obstructing field"),1,0)) | U8: =IF(A8="","",IF(AND(M8=1,N8="catch",P8<>""),1,0)) | V8: =IF(A8="","",IF(AND(M8=1,N8="stumping",P8<>""),1,0)) | W8: =IF(A8="","",IF(N8="run out direct",1,0)) | X8: =IF(A8="","",IF(N8="run out assist",1,0)) | Y8: =IF(A8="","",IF(AND(L8=1,S8=0),1,0)) | Z8: =IF(A8="","",I8+IF(OR(K8="wide",K8="no ball"),J8,0))
S9: =IF(A9="","",I9+J9) | T9: =IF(A9="","",IF(AND(M9=1,N9<>"run out direct",N9<>"run out assist",N9<>"retired hurt",N9<>"obstructing field"),1,0)) | U9: =IF(A9="","",IF(AND(M9=1,N9="catch",P9<>""),1,0)) | V9: =IF(A9="","",IF(AND(M9=1,N9="stumping",P9<>""),1,0)) | W9: =IF(A9="","",IF(N9="run out direct",1,0)) | X9: =IF(A9="","",IF(N9="run out assist",1,0)) | Y9: =IF(A9="","",IF(AND(L9=1,S9=0),1,0)) | Z9: =IF(A9="","",I9+IF(OR(K9="wide",K9="no ball"),J9,0))
S10: =IF(A10="","",I10+J10) | T10: =IF(A10="","",IF(AND(M10=1,N10<>"run out direct",N10<>"run out assist",N10<>"retired hurt",N10<>"obstructing field"),1,0)) | U10: =IF(A10="","",IF(AND(M10=1,N10="catch",P10<>""),1,0)) | V10: =IF(A10="","",IF(AND(M10=1,N10="stumping",P10<>""),1,0)) | W10: =IF(A10="","",IF(N10="run out direct",1,0)) | X10: =IF(A10="","",IF(N10="run out assist",1,0)) | Y10: =IF(A10="","",IF(AND(L10=1,S10=0),1,0)) | Z10: =IF(A10="","",I10+IF(OR(K10="wide",K10="no ball"),J10,0))
S11: =IF(A11="","",I11+J11) | T11: =IF(A11="","",IF(AND(M11=1,N11<>"run out direct",N11<>"run out assist",N11<>"retired hurt",N11<>"obstructing field"),1,0)) | U11: =IF(A11="","",IF(AND(M11=1,N11="catch",P11<>""),1,0)) | V11: =IF(A11="","",IF(AND(M11=1,N11="stumping",P11<>""),1,0)) | W11: =IF(A11="","",IF(N11="run out direct",1,0)) | X11: =IF(A11="","",IF(N11="run out assist",1,0)) | Y11: =IF(A11="","",IF(AND(L11=1,S11=0),1,0)) | Z11: =IF(A11="","",I11+IF(OR(K11="wide",K11="no ball"),J11,0))
S12: =IF(A12="","",I12+J12) | T12: =IF(A12="","",IF(AND(M12=1,N12<>"run out direct",N12<>"run out assist",N12<>"retired hurt",N12<>"obstructing field"),1,0)) | U12: =IF(A12="","",IF(AND(M12=1,N12="catch",P12<>""),1,0)) | V12: =IF(A12="","",IF(AND(M12=1,N12="stumping",P12<>""),1,0)) | W12: =IF(A12="","",IF(N12="run out direct",1,0)) | X12: =IF(A12="","",IF(N12="run out assist",1,0)) | Y12: =IF(A12="","",IF(AND(L12=1,S12=0),1,0)) | Z12: =IF(A12="","",I12+IF(OR(K12="wide",K12="no ball"),J12,0))
S13: =IF(A13="","",I13+J13) | T13: =IF(A13="","",IF(AND(M13=1,N13<>"run out direct",N13<>"run out assist",N13<>"retired hurt",N13<>"obstructing field"),1,0)) | U13: =IF(A13="","",IF(AND(M13=1,N13="catch",P13<>""),1,0)) | V13: =IF(A13="","",IF(AND(M13=1,N13="stumping",P13<>""),1,0)) | W13: =IF(A13="","",IF(N13="run out direct",1,0)) | X13: =IF(A13="","",IF(N13="run out assist",1,0)) | Y13: =IF(A13="","",IF(AND(L13=1,S13=0),1,0)) | Z13: =IF(A13="","",I13+IF(OR(K13="wide",K13="no ball"),J13,0))
... S501: =IF(A501="","",I501+J501) | T501: =IF(A501="","",IF(AND(M501=1,N501<>"run out direct",N501<>"run out assist",N501<>"retired hurt",N501<>"obstructing field"),1,0)) | U501: =IF(A501="","",IF(AND(M501=1,N501="catch",P501<>""),1,0)) | V501: =IF(A501="","",IF(AND(M501=1,N501="stumping",P501<>""),1,0)) | W501: =IF(A501="","",IF(N501="run out direct",1,0)) | X501: =IF(A501="","",IF(N501="run out assist",1,0)) | Y501: =IF(A501="","",IF(AND(L501=1,S501=0),1,0)) | Z501: =IF(A501="","",I501+IF(OR(K501="wide",K501="no ball"),J501,0))

Sheet OverSummary
A1: MatchID | B1: Innings | C1: Over | D1: BowlerID | E1: BallsLegal | F1: BowlerRunsConceded | G1: IsMaiden (1/0) | H1: Notes
J2: Optional helper
J3: Each row = one completed over. Fill only if you want maiden-over scoring.

Sheet PlayerPoints
A1: MatchID | B1: PlayerID | C1: PlayerName | D1: Role | E1: RealTeam | F1: InStartingXI | G1: Runs | H1: Fours | I1: Sixes | J1: Wickets | K1: Catches | L1: Stumpings | M1: RunOutDirect | N1: RunOutAssist | O1: Maidens | P1: BattingPts | Q1: BatBonusPts | R1: BowlingPts | S1: BowlingBonusPts | T1: FieldingPts | U1: TotalPts
A2: =MatchSquad!A2 -> M001 | B2: =MatchSquad!B2 -> P201 | C2: =MatchSquad!C2 -> Rajat Patidar | D2: =MatchSquad!D2 -> BAT | E2: =MatchSquad!E2 -> RCB | F2: =MatchSquad!G2 -> 0 | G2: =IF(A2="","",SUMIFS(BallByBall!$I$2:$I$501,BallByBall!$B$2:$B$501,A2,BallByBall!$F$2:$F$501,B2)) -> 0 | H2: =IF(A2="","",COUNTIFS(BallByBall!$B$2:$B$501,A2,BallByBall!$F$2:$F$501,B2,BallByBall!$Q$2:$Q$501,1)) -> 0 | I2: =IF(A2="","",COUNTIFS(BallByBall!$B$2:$B$501,A2,BallByBall!$F$2:$F$501,B2,BallByBall!$R$2:$R$501,1)) -> 0 | J2: =IF(A2="","",SUMIFS(BallByBall!$T$2:$T$501,BallByBall!$B$2:$B$501,A2,BallByBall!$H$2:$H$501,B2)) -> 0 | K2: =IF(A2="","",SUMIFS(BallByBall!$U$2:$U$501,BallByBall!$B$2:$B$501,A2,BallByBall!$P$2:$P$501,B2)) -> 0 | L2: =IF(A2="","",SUMIFS(BallByBall!$V$2:$V$501,BallByBall!$B$2:$B$501,A2,BallByBall!$P$2:$P$501,B2)) -> 0 | M2: =IF(A2="","",SUMIFS(BallByBall!$W$2:$W$501,BallByBall!$B$2:$B$501,A2,BallByBall!$P$2:$P$501,B2)) -> 0 | N2: =IF(A2="","",SUMIFS(BallByBall!$X$2:$X$501,BallByBall!$B$2:$B$501,A2,BallByBall!$P$2:$P$501,B2)) -> 0 | O2: =IF(A2="","",SUMIFS(OverSummary!$G$2:$G$101,OverSummary!$A$2:$A$101,A2,OverSummary!$D$2:$D$101,B2)) -> 0 | P2: =IF(A2="","",G2*Rules!$B$13+H2*Rules!$B$14+I2*Rules!$B$15) -> 0 | Q2: =IF(A2="","",IF(G2>=100,Rules!$B$18,IF(G2>=50,Rules!$B$17,IF(G2>=30,Rules!$B$16,0)))+IF(AND(F2=1,D2<>"BWL",G2=0),Rules!$B$27,0)) -> 0 | R2: =IF(A2="","",J2*Rules!$B$19+O2*Rules!$B$22) -> 0 | S2: =IF(A2="","",IF(J2>=4,Rules!$B$21,IF(J2>=3,Rules!$B$20,0))) -> 0 | T2: =IF(A2="","",K2*Rules!$B$23+L2*Rules!$B$24+M2*Rules!$B$25+N2*Rules!$B$26) -> 0 | U2: =IF(A2="","",P2+Q2+R2+S2+T2) -> 0
A3: =MatchSquad!A3 -> M001 | B3: =MatchSquad!B3 -> P202 | C3: =MatchSquad!C3 -> Devdutt Padikkal | D3: =MatchSquad!D3 -> BAT | E3: =MatchSquad!E3 -> RCB | F3: =MatchSquad!G3 -> 0 | G3: =IF(A3="","",SUMIFS(BallByBall!$I$2:$I$501,BallByBall!$B$2:$B$501,A3,BallByBall!$F$2:$F$501,B3)) -> 0 | H3: =IF(A3="","",COUNTIFS(BallByBall!$B$2:$B$501,A3,BallByBall!$F$2:$F$501,B3,BallByBall!$Q$2:$Q$501,1)) -> 0 | I3: =IF(A3="","",COUNTIFS(BallByBall!$B$2:$B$501,A3,BallByBall!$F$2:$F$501,B3,BallByBall!$R$2:$R$501,1)) -> 0 | J3: =IF(A3="","",SUMIFS(BallByBall!$T$2:$T$501,BallByBall!$B$2:$B$501,A3,BallByBall!$H$2:$H$501,B3)) -> 0 | K3: =IF(A3="","",SUMIFS(BallByBall!$U$2:$U$501,BallByBall!$B$2:$B$501,A3,BallByBall!$P$2:$P$501,B3)) -> 0 | L3: =IF(A3="","",SUMIFS(BallByBall!$V$2:$V$501,BallByBall!$B$2:$B$501,A3,BallByBall!$P$2:$P$501,B3)) -> 0 | M3: =IF(A3="","",SUMIFS(BallByBall!$W$2:$W$501,BallByBall!$B$2:$B$501,A3,BallByBall!$P$2:$P$501,B3)) -> 0 | N3: =IF(A3="","",SUMIFS(BallByBall!$X$2:$X$501,BallByBall!$B$2:$B$501,A3,BallByBall!$P$2:$P$501,B3)) -> 0 | O3: =IF(A3="","",SUMIFS(OverSummary!$G$2:$G$101,OverSummary!$A$2:$A$101,A3,OverSummary!$D$2:$D$101,B3)) -> 0 | P3: =IF(A3="","",G3*Rules!$B$13+H3*Rules!$B$14+I3*Rules!$B$15) -> 0 | Q3: =IF(A3="","",IF(G3>=100,Rules!$B$18,IF(G3>=50,Rules!$B$17,IF(G3>=30,Rules!$B$16,0)))+IF(AND(F3=1,D3<>"BWL",G3=0),Rules!$B$27,0)) -> 0 | R3: =IF(A3="","",J3*Rules!$B$19+O3*Rules!$B$22) -> 0 | S3: =IF(A3="","",IF(J3>=4,Rules!$B$21,IF(J3>=3,Rules!$B$20,0))) -> 0 | T3: =IF(A3="","",K3*Rules!$B$23+L3*Rules!$B$24+M3*Rules!$B$25+N3*Rules!$B$26) -> 0 | U3: =IF(A3="","",P3+Q3+R3+S3+T3) -> 0
A4: =MatchSquad!A4 -> M001 | B4: =MatchSquad!B4 -> P203 | C4: =MatchSquad!C4 -> Virat Kohli | D4: =MatchSquad!D4 -> BAT | E4: =MatchSquad!E4 -> RCB | F4: =MatchSquad!G4 -> 0 | G4: =IF(A4="","",SUMIFS(BallByBall!$I$2:$I$501,BallByBall!$B$2:$B$501,A4,BallByBall!$F$2:$F$501,B4)) -> 0 | H4: =IF(A4="","",COUNTIFS(BallByBall!$B$2:$B$501,A4,BallByBall!$F$2:$F$501,B4,BallByBall!$Q$2:$Q$501,1)) -> 0 | I4: =IF(A4="","",COUNTIFS(BallByBall!$B$2:$B$501,A4,BallByBall!$F$2:$F$501,B4,BallByBall!$R$2:$R$501,1)) -> 0 | J4: =IF(A4="","",SUMIFS(BallByBall!$T$2:$T$501,BallByBall!$B$2:$B$501,A4,BallByBall!$H$2:$H$501,B4)) -> 0 | K4: =IF(A4="","",SUMIFS(BallByBall!$U$2:$U$501,BallByBall!$B$2:$B$501,A4,BallByBall!$P$2:$P$501,B4)) -> 0 | L4: =IF(A4="","",SUMIFS(BallByBall!$V$2:$V$501,BallByBall!$B$2:$B$501,A4,BallByBall!$P$2:$P$501,B4)) -> 0 | M4: =IF(A4="","",SUMIFS(BallByBall!$W$2:$W$501,BallByBall!$B$2:$B$501,A4,BallByBall!$P$2:$P$501,B4)) -> 0 | N4: =IF(A4="","",SUMIFS(BallByBall!$X$2:$X$501,BallByBall!$B$2:$B$501,A4,BallByBall!$P$2:$P$501,B4)) -> 0 | O4: =IF(A4="","",SUMIFS(OverSummary!$G$2:$G$101,OverSummary!$A$2:$A$101,A4,OverSummary!$D$2:$D$101,B4)) -> 0 | P4: =IF(A4="","",G4*Rules!$B$13+H4*Rules!$B$14+I4*Rules!$B$15) -> 0 | Q4: =IF(A4="","",IF(G4>=100,Rules!$B$18,IF(G4>=50,Rules!$B$17,IF(G4>=30,Rules!$B$16,0)))+IF(AND(F4=1,D4<>"BWL",G4=0),Rules!$B$27,0)) -> 0 | R4: =IF(A4="","",J4*Rules!$B$19+O4*Rules!$B$22) -> 0 | S4: =IF(A4="","",IF(J4>=4,Rules!$B$21,IF(J4>=3,Rules!$B$20,0))) -> 0 | T4: =IF(A4="","",K4*Rules!$B$23+L4*Rules!$B$24+M4*Rules!$B$25+N4*Rules!$B$26) -> 0 | U4: =IF(A4="","",P4+Q4+R4+S4+T4) -> 0
A5: =MatchSquad!A5 -> M001 | B5: =MatchSquad!B5 -> P204 | C5: =MatchSquad!C5 -> Phil Salt | D5: =MatchSquad!D5 -> WK | E5: =MatchSquad!E5 -> RCB | F5: =MatchSquad!G5 -> 0 | G5: =IF(A5="","",SUMIFS(BallByBall!$I$2:$I$501,BallByBall!$B$2:$B$501,A5,BallByBall!$F$2:$F$501,B5)) -> 0 | H5: =IF(A5="","",COUNTIFS(BallByBall!$B$2:$B$501,A5,BallByBall!$F$2:$F$501,B5,BallByBall!$Q$2:$Q$501,1)) -> 0 | I5: =IF(A5="","",COUNTIFS(BallByBall!$B$2:$B$501,A5,BallByBall!$F$2:$F$501,B5,BallByBall!$R$2:$R$501,1)) -> 0 | J5: =IF(A5="","",SUMIFS(BallByBall!$T$2:$T$501,BallByBall!$B$2:$B$501,A5,BallByBall!$H$2:$H$501,B5)) -> 0 | K5: =IF(A5="","",SUMIFS(BallByBall!$U$2:$U$501,BallByBall!$B$2:$B$501,A5,BallByBall!$P$2:$P$501,B5)) -> 0 | L5: =IF(A5="","",SUMIFS(BallByBall!$V$2:$V$501,BallByBall!$B$2:$B$501,A5,BallByBall!$P$2:$P$501,B5)) -> 0 | M5: =IF(A5="","",SUMIFS(BallByBall!$W$2:$W$501,BallByBall!$B$2:$B$501,A5,BallByBall!$P$2:$P$501,B5)) -> 0 | N5: =IF(A5="","",SUMIFS(BallByBall!$X$2:$X$501,BallByBall!$B$2:$B$501,A5,BallByBall!$P$2:$P$501,B5)) -> 0 | O5: =IF(A5="","",SUMIFS(OverSummary!$G$2:$G$101,OverSummary!$A$2:$A$101,A5,OverSummary!$D$2:$D$101,B5)) -> 0 | P5: =IF(A5="","",G5*Rules!$B$13+H5*Rules!$B$14+I5*Rules!$B$15) -> 0 | Q5: =IF(A5="","",IF(G5>=100,Rules!$B$18,IF(G5>=50,Rules!$B$17,IF(G5>=30,Rules!$B$16,0)))+IF(AND(F5=1,D5<>"BWL",G5=0),Rules!$B$27,0)) -> 0 | R5: =IF(A5="","",J5*Rules!$B$19+O5*Rules!$B$22) -> 0 | S5: =IF(A5="","",IF(J5>=4,Rules!$B$21,IF(J5>=3,Rules!$B$20,0))) -> 0 | T5: =IF(A5="","",K5*Rules!$B$23+L5*Rules!$B$24+M5*Rules!$B$25+N5*Rules!$B$26) -> 0 | U5: =IF(A5="","",P5+Q5+R5+S5+T5) -> 0
A6: =MatchSquad!A6 -> M001 | B6: =MatchSquad!B6 -> P205 | C6: =MatchSquad!C6 -> Jitesh Sharma | D6: =MatchSquad!D6 -> WK | E6: =MatchSquad!E6 -> RCB | F6: =MatchSquad!G6 -> 0 | G6: =IF(A6="","",SUMIFS(BallByBall!$I$2:$I$501,BallByBall!$B$2:$B$501,A6,BallByBall!$F$2:$F$501,B6)) -> 0 | H6: =IF(A6="","",COUNTIFS(BallByBall!$B$2:$B$501,A6,BallByBall!$F$2:$F$501,B6,BallByBall!$Q$2:$Q$501,1)) -> 0 | I6: =IF(A6="","",COUNTIFS(BallByBall!$B$2:$B$501,A6,BallByBall!$F$2:$F$501,B6,BallByBall!$R$2:$R$501,1)) -> 0 | J6: =IF(A6="","",SUMIFS(BallByBall!$T$2:$T$501,BallByBall!$B$2:$B$501,A6,BallByBall!$H$2:$H$501,B6)) -> 0 | K6: =IF(A6="","",SUMIFS(BallByBall!$U$2:$U$501,BallByBall!$B$2:$B$501,A6,BallByBall!$P$2:$P$501,B6)) -> 0 | L6: =IF(A6="","",SUMIFS(BallByBall!$V$2:$V$501,BallByBall!$B$2:$B$501,A6,BallByBall!$P$2:$P$501,B6)) -> 0 | M6: =IF(A6="","",SUMIFS(BallByBall!$W$2:$W$501,BallByBall!$B$2:$B$501,A6,BallByBall!$P$2:$P$501,B6)) -> 0 | N6: =IF(A6="","",SUMIFS(BallByBall!$X$2:$X$501,BallByBall!$B$2:$B$501,A6,BallByBall!$P$2:$P$501,B6)) -> 0 | O6: =IF(A6="","",SUMIFS(OverSummary!$G$2:$G$101,OverSummary!$A$2:$A$101,A6,OverSummary!$D$2:$D$101,B6)) -> 0 | P6: =IF(A6="","",G6*Rules!$B$13+H6*Rules!$B$14+I6*Rules!$B$15) -> 0 | Q6: =IF(A6="","",IF(G6>=100,Rules!$B$18,IF(G6>=50,Rules!$B$17,IF(G6>=30,Rules!$B$16,0)))+IF(AND(F6=1,D6<>"BWL",G6=0),Rules!$B$27,0)) -> 0 | R6: =IF(A6="","",J6*Rules!$B$19+O6*Rules!$B$22) -> 0 | S6: =IF(A6="","",IF(J6>=4,Rules!$B$21,IF(J6>=3,Rules!$B$20,0))) -> 0 | T6: =IF(A6="","",K6*Rules!$B$23+L6*Rules!$B$24+M6*Rules!$B$25+N6*Rules!$B$26) -> 0 | U6: =IF(A6="","",P6+Q6+R6+S6+T6) -> 0
A7: =MatchSquad!A7 -> M001 | B7: =MatchSquad!B7 -> P206 | C7: =MatchSquad!C7 -> Jordan Cox | D7: =MatchSquad!D7 -> WK | E7: =MatchSquad!E7 -> RCB | F7: =MatchSquad!G7 -> 0 | G7: =IF(A7="","",SUMIFS(BallByBall!$I$2:$I$501,BallByBall!$B$2:$B$501,A7,BallByBall!$F$2:$F$501,B7)) -> 0 | H7: =IF(A7="","",COUNTIFS(BallByBall!$B$2:$B$501,A7,BallByBall!$F$2:$F$501,B7,BallByBall!$Q$2:$Q$501,1)) -> 0 | I7: =IF(A7="","",COUNTIFS(BallByBall!$B$2:$B$501,A7,BallByBall!$F$2:$F$501,B7,BallByBall!$R$2:$R$501,1)) -> 0 | J7: =IF(A7="","",SUMIFS(BallByBall!$T$2:$T$501,BallByBall!$B$2:$B$501,A7,BallByBall!$H$2:$H$501,B7)) -> 0 | K7: =IF(A7="","",SUMIFS(BallByBall!$U$2:$U$501,BallByBall!$B$2:$B$501,A7,BallByBall!$P$2:$P$501,B7)) -> 0 | L7: =IF(A7="","",SUMIFS(BallByBall!$V$2:$V$501,BallByBall!$B$2:$B$501,A7,BallByBall!$P$2:$P$501,B7)) -> 0 | M7: =IF(A7="","",SUMIFS(BallByBall!$W$2:$W$501,BallByBall!$B$2:$B$501,A7,BallByBall!$P$2:$P$501,B7)) -> 0 | N7: =IF(A7="","",SUMIFS(BallByBall!$X$2:$X$501,BallByBall!$B$2:$B$501,A7,BallByBall!$P$2:$P$501,B7)) -> 0 | O7: =IF(A7="","",SUMIFS(OverSummary!$G$2:$G$101,OverSummary!$A$2:$A$101,A7,OverSummary!$D$2:$D$101,B7)) -> 0 | P7: =IF(A7="","",G7*Rules!$B$13+H7*Rules!$B$14+I7*Rules!$B$15) -> 0 | Q7: =IF(A7="","",IF(G7>=100,Rules!$B$18,IF(G7>=50,Rules!$B$17,IF(G7>=30,Rules!$B$16,0)))+IF(AND(F7=1,D7<>"BWL",G7=0),Rules!$B$27,0)) -> 0 | R7: =IF(A7="","",J7*Rules!$B$19+O7*Rules!$B$22) -> 0 | S7: =IF(A7="","",IF(J7>=4,Rules!$B$21,IF(J7>=3,Rules!$B$20,0))) -> 0 | T7: =IF(A7="","",K7*Rules!$B$23+L7*Rules!$B$24+M7*Rules!$B$25+N7*Rules!$B$26) -> 0 | U7: =IF(A7="","",P7+Q7+R7+S7+T7) -> 0
A8: =MatchSquad!A8 -> M001 | B8: =MatchSquad!B8 -> P207 | C8: =MatchSquad!C8 -> Krunal Pandya | D8: =MatchSquad!D8 -> AR | E8: =MatchSquad!E8 -> RCB | F8: =MatchSquad!G8 -> 0 | G8: =IF(A8="","",SUMIFS(BallByBall!$I$2:$I$501,BallByBall!$B$2:$B$501,A8,BallByBall!$F$2:$F$501,B8)) -> 0 | H8: =IF(A8="","",COUNTIFS(BallByBall!$B$2:$B$501,A8,BallByBall!$F$2:$F$501,B8,BallByBall!$Q$2:$Q$501,1)) -> 0 | I8: =IF(A8="","",COUNTIFS(BallByBall!$B$2:$B$501,A8,BallByBall!$F$2:$F$501,B8,BallByBall!$R$2:$R$501,1)) -> 0 | J8: =IF(A8="","",SUMIFS(BallByBall!$T$2:$T$501,BallByBall!$B$2:$B$501,A8,BallByBall!$H$2:$H$501,B8)) -> 0 | K8: =IF(A8="","",SUMIFS(BallByBall!$U$2:$U$501,BallByBall!$B$2:$B$501,A8,BallByBall!$P$2:$P$501,B8)) -> 0 | L8: =IF(A8="","",SUMIFS(BallByBall!$V$2:$V$501,BallByBall!$B$2:$B$501,A8,BallByBall!$P$2:$P$501,B8)) -> 0 | M8: =IF(A8="","",SUMIFS(BallByBall!$W$2:$W$501,BallByBall!$B$2:$B$501,A8,BallByBall!$P$2:$P$501,B8)) -> 0 | N8: =IF(A8="","",SUMIFS(BallByBall!$X$2:$X$501,BallByBall!$B$2:$B$501,A8,BallByBall!$P$2:$P$501,B8)) -> 0 | O8: =IF(A8="","",SUMIFS(OverSummary!$G$2:$G$101,OverSummary!$A$2:$A$101,A8,OverSummary!$D$2:$D$101,B8)) -> 0 | P8: =IF(A8="","",G8*Rules!$B$13+H8*Rules!$B$14+I8*Rules!$B$15) -> 0 | Q8: =IF(A8="","",IF(G8>=100,Rules!$B$18,IF(G8>=50,Rules!$B$17,IF(G8>=30,Rules!$B$16,0)))+IF(AND(F8=1,D8<>"BWL",G8=0),Rules!$B$27,0)) -> 0 | R8: =IF(A8="","",J8*Rules!$B$19+O8*Rules!$B$22) -> 0 | S8: =IF(A8="","",IF(J8>=4,Rules!$B$21,IF(J8>=3,Rules!$B$20,0))) -> 0 | T8: =IF(A8="","",K8*Rules!$B$23+L8*Rules!$B$24+M8*Rules!$B$25+N8*Rules!$B$26) -> 0 | U8: =IF(A8="","",P8+Q8+R8+S8+T8) -> 0
A9: =MatchSquad!A9 -> M001 | B9: =MatchSquad!B9 -> P208 | C9: =MatchSquad!C9 -> Swapnil Singh | D9: =MatchSquad!D9 -> AR | E9: =MatchSquad!E9 -> RCB | F9: =MatchSquad!G9 -> 0 | G9: =IF(A9="","",SUMIFS(BallByBall!$I$2:$I$501,BallByBall!$B$2:$B$501,A9,BallByBall!$F$2:$F$501,B9)) -> 0 | H9: =IF(A9="","",COUNTIFS(BallByBall!$B$2:$B$501,A9,BallByBall!$F$2:$F$501,B9,BallByBall!$Q$2:$Q$501,1)) -> 0 | I9: =IF(A9="","",COUNTIFS(BallByBall!$B$2:$B$501,A9,BallByBall!$F$2:$F$501,B9,BallByBall!$R$2:$R$501,1)) -> 0 | J9: =IF(A9="","",SUMIFS(BallByBall!$T$2:$T$501,BallByBall!$B$2:$B$501,A9,BallByBall!$H$2:$H$501,B9)) -> 0 | K9: =IF(A9="","",SUMIFS(BallByBall!$U$2:$U$501,BallByBall!$B$2:$B$501,A9,BallByBall!$P$2:$P$501,B9)) -> 0 | L9: =IF(A9="","",SUMIFS(BallByBall!$V$2:$V$501,BallByBall!$B$2:$B$501,A9,BallByBall!$P$2:$P$501,B9)) -> 0 | M9: =IF(A9="","",SUMIFS(BallByBall!$W$2:$W$501,BallByBall!$B$2:$B$501,A9,BallByBall!$P$2:$P$501,B9)) -> 0 | N9: =IF(A9="","",SUMIFS(BallByBall!$X$2:$X$501,BallByBall!$B$2:$B$501,A9,BallByBall!$P$2:$P$501,B9)) -> 0 | O9: =IF(A9="","",SUMIFS(OverSummary!$G$2:$G$101,OverSummary!$A$2:$A$101,A9,OverSummary!$D$2:$D$101,B9)) -> 0 | P9: =IF(A9="","",G9*Rules!$B$13+H9*Rules!$B$14+I9*Rules!$B$15) -> 0 | Q9: =IF(A9="","",IF(G9>=100,Rules!$B$18,IF(G9>=50,Rules!$B$17,IF(G9>=30,Rules!$B$16,0)))+IF(AND(F9=1,D9<>"BWL",G9=0),Rules!$B$27,0)) -> 0 | R9: =IF(A9="","",J9*Rules!$B$19+O9*Rules!$B$22) -> 0 | S9: =IF(A9="","",IF(J9>=4,Rules!$B$21,IF(J9>=3,Rules!$B$20,0))) -> 0 | T9: =IF(A9="","",K9*Rules!$B$23+L9*Rules!$B$24+M9*Rules!$B$25+N9*Rules!$B$26) -> 0 | U9: =IF(A9="","",P9+Q9+R9+S9+T9) -> 0
A10: =MatchSquad!A10 -> M001 | B10: =MatchSquad!B10 -> P209 | C10: =MatchSquad!C10 -> Tim David | D10: =MatchSquad!D10 -> AR | E10: =MatchSquad!E10 -> RCB | F10: =MatchSquad!G10 -> 0 | G10: =IF(A10="","",SUMIFS(BallByBall!$I$2:$I$501,BallByBall!$B$2:$B$501,A10,BallByBall!$F$2:$F$501,B10)) -> 0 | H10: =IF(A10="","",COUNTIFS(BallByBall!$B$2:$B$501,A10,BallByBall!$F$2:$F$501,B10,BallByBall!$Q$2:$Q$501,1)) -> 0 | I10: =IF(A10="","",COUNTIFS(BallByBall!$B$2:$B$501,A10,BallByBall!$F$2:$F$501,B10,BallByBall!$R$2:$R$501,1)) -> 0 | J10: =IF(A10="","",SUMIFS(BallByBall!$T$2:$T$501,BallByBall!$B$2:$B$501,A10,BallByBall!$H$2:$H$501,B10)) -> 0 | K10: =IF(A10="","",SUMIFS(BallByBall!$U$2:$U$501,BallByBall!$B$2:$B$501,A10,BallByBall!$P$2:$P$501,B10)) -> 0 | L10: =IF(A10="","",SUMIFS(BallByBall!$V$2:$V$501,BallByBall!$B$2:$B$501,A10,BallByBall!$P$2:$P$501,B10)) -> 0 | M10: =IF(A10="","",SUMIFS(BallByBall!$W$2:$W$501,BallByBall!$B$2:$B$501,A10,BallByBall!$P$2:$P$501,B10)) -> 0 | N10: =IF(A10="","",SUMIFS(BallByBall!$X$2:$X$501,BallByBall!$B$2:$B$501,A10,BallByBall!$P$2:$P$501,B10)) -> 0 | O10: =IF(A10="","",SUMIFS(OverSummary!$G$2:$G$101,OverSummary!$A$2:$A$101,A10,OverSummary!$D$2:$D$101,B10)) -> 0 | P10: =IF(A10="","",G10*Rules!$B$13+H10*Rules!$B$14+I10*Rules!$B$15) -> 0 | Q10: =IF(A10="","",IF(G10>=100,Rules!$B$18,IF(G10>=50,Rules!$B$17,IF(G10>=30,Rules!$B$16,0)))+IF(AND(F10=1,D10<>"BWL",G10=0),Rules!$B$27,0)) -> 0 | R10: =IF(A10="","",J10*Rules!$B$19+O10*Rules!$B$22) -> 0 | S10: =IF(A10="","",IF(J10>=4,Rules!$B$21,IF(J10>=3,Rules!$B$20,0))) -> 0 | T10: =IF(A10="","",K10*Rules!$B$23+L10*Rules!$B$24+M10*Rules!$B$25+N10*Rules!$B$26) -> 0 | U10: =IF(A10="","",P10+Q10+R10+S10+T10) -> 0
A11: =MatchSquad!A11 -> M001 | B11: =MatchSquad!B11 -> P210 | C11: =MatchSquad!C11 -> Romario Shepherd | D11: =MatchSquad!D11 -> AR | E11: =MatchSquad!E11 -> RCB | F11: =MatchSquad!G11 -> 0 | G11: =IF(A11="","",SUMIFS(BallByBall!$I$2:$I$501,BallByBall!$B$2:$B$501,A11,BallByBall!$F$2:$F$501,B11)) -> 0 | H11: =IF(A11="","",COUNTIFS(BallByBall!$B$2:$B$501,A11,BallByBall!$F$2:$F$501,B11,BallByBall!$Q$2:$Q$501,1)) -> 0 | I11: =IF(A11="","",COUNTIFS(BallByBall!$B$2:$B$501,A11,BallByBall!$F$2:$F$501,B11,BallByBall!$R$2:$R$501,1)) -> 0 | J11: =IF(A11="","",SUMIFS(BallByBall!$T$2:$T$501,BallByBall!$B$2:$B$501,A11,BallByBall!$H$2:$H$501,B11)) -> 0 | K11: =IF(A11="","",SUMIFS(BallByBall!$U$2:$U$501,BallByBall!$B$2:$B$501,A11,BallByBall!$P$2:$P$501,B11)) -> 0 | L11: =IF(A11="","",SUMIFS(BallByBall!$V$2:$V$501,BallByBall!$B$2:$B$501,A11,BallByBall!$P$2:$P$501,B11)) -> 0 | M11: =IF(A11="","",SUMIFS(BallByBall!$W$2:$W$501,BallByBall!$B$2:$B$501,A11,BallByBall!$P$2:$P$501,B11)) -> 0 | N11: =IF(A11="","",SUMIFS(BallByBall!$X$2:$X$501,BallByBall!$B$2:$B$501,A11,BallByBall!$P$2:$P$501,B11)) -> 0 | O11: =IF(A11="","",SUMIFS(OverSummary!$G$2:$G$101,OverSummary!$A$2:$A$101,A11,OverSummary!$D$2:$D$101,B11)) -> 0 | P11: =IF(A11="","",G11*Rules!$B$13+H11*Rules!$B$14+I11*Rules!$B$15) -> 0 | Q11: =IF(A11="","",IF(G11>=100,Rules!$B$18,IF(G11>=50,Rules!$B$17,IF(G11>=30,Rules!$B$16,0)))+IF(AND(F11=1,D11<>"BWL",G11=0),Rules!$B$27,0)) -> 0 | R11: =IF(A11="","",J11*Rules!$B$19+O11*Rules!$B$22) -> 0 | S11: =IF(A11="","",IF(J11>=4,Rules!$B$21,IF(J11>=3,Rules!$B$20,0))) -> 0 | T11: =IF(A11="","",K11*Rules!$B$23+L11*Rules!$B$24+M11*Rules!$B$25+N11*Rules!$B$26) -> 0 | U11: =IF(A11="","",P11+Q11+R11+S11+T11) -> 0
A12: =MatchSquad!A12 -> M001 | B12: =MatchSquad!B12 -> P211 | C12: =MatchSquad!C12 -> Jacob Bethell | D12: =MatchSquad!D12 -> AR | E12: =MatchSquad!E12 -> RCB | F12: =MatchSquad!G12 -> 0 | G12: =IF(A12="","",SUMIFS(BallByBall!$I$2:$I$501,BallByBall!$B$2:$B$501,A12,BallByBall!$F$2:$F$501,B12)) -> 0 | H12: =IF(A12="","",COUNTIFS(BallByBall!$B$2:$B$501,A12,BallByBall!$F$2:$F$501,B12,BallByBall!$Q$2:$Q$501,1)) -> 0 | I12: =IF(A12="","",COUNTIFS(BallByBall!$B$2:$B$501,A12,BallByBall!$F$2:$F$501,B12,BallByBall!$R$2:$R$501,1)) -> 0 | J12: =IF(A12="","",SUMIFS(BallByBall!$T$2:$T$501,BallByBall!$B$2:$B$501,A12,BallByBall!$H$2:$H$501,B12)) -> 0 | K12: =IF(A12="","",SUMIFS(BallByBall!$U$2:$U$501,BallByBall!$B$2:$B$501,A12,BallByBall!$P$2:$P$501,B12)) -> 0 | L12: =IF(A12="","",SUMIFS(BallByBall!$V$2:$V$501,BallByBall!$B$2:$B$501,A12,BallByBall!$P$2:$P$501,B12)) -> 0 | M12: =IF(A12="","",SUMIFS(BallByBall!$W$2:$W$501,BallByBall!$B$2:$B$501,A12,BallByBall!$P$2:$P$501,B12)) -> 0 | N12: =IF(A12="","",SUMIFS(BallByBall!$X$2:$X$501,BallByBall!$B$2:$B$501,A12,BallByBall!$P$2:$P$501,B12)) -> 0 | O12: =IF(A12="","",SUMIFS(OverSummary!$G$2:$G$101,OverSummary!$A$2:$A$101,A12,OverSummary!$D$2:$D$101,B12)) -> 0 | P12: =IF(A12="","",G12*Rules!$B$13+H12*Rules!$B$14+I12*Rules!$B$15) -> 0 | Q12: =IF(A12="","",IF(G12>=100,Rules!$B$18,IF(G12>=50,Rules!$B$17,IF(G12>=30,Rules!$B$16,0)))+IF(AND(F12=1,D12<>"BWL",G12=0),Rules!$B$27,0)) -> 0 | R12: =IF(A12="","",J12*Rules!$B$19+O12*Rules!$B$22) -> 0 | S12: =IF(A12="","",IF(J12>=4,Rules!$B$21,IF(J12>=3,Rules!$B$20,0))) -> 0 | T12: =IF(A12="","",K12*Rules!$B$23+L12*Rules!$B$24+M12*Rules!$B$25+N12*Rules!$B$26) -> 0 | U12: =IF(A12="","",P12+Q12+R12+S12+T12) -> 0
A13: =MatchSquad!A13 -> M001 | B13: =MatchSquad!B13 -> P212 | C13: =MatchSquad!C13 -> Venkatesh Iyer | D13: =MatchSquad!D13 -> AR | E13: =MatchSquad!E13 -> RCB | F13: =MatchSquad!G13 -> 0 | G13: =IF(A13="","",SUMIFS(BallByBall!$I$2:$I$501,BallByBall!$B$2:$B$501,A13,BallByBall!$F$2:$F$501,B13)) -> 0 | H13: =IF(A13="","",COUNTIFS(BallByBall!$B$2:$B$501,A13,BallByBall!$F$2:$F$501,B13,BallByBall!$Q$2:$Q$501,1)) -> 0 | I13: =IF(A13="","",COUNTIFS(BallByBall!$B$2:$B$501,A13,BallByBall!$F$2:$F$501,B13,BallByBall!$R$2:$R$501,1)) -> 0 | J13: =IF(A13="","",SUMIFS(BallByBall!$T$2:$T$501,BallByBall!$B$2:$B$501,A13,BallByBall!$H$2:$H$501,B13)) -> 0 | K13: =IF(A13="","",SUMIFS(BallByBall!$U$2:$U$501,BallByBall!$B$2:$B$501,A13,BallByBall!$P$2:$P$501,B13)) -> 0 | L13: =IF(A13="","",SUMIFS(BallByBall!$V$2:$V$501,BallByBall!$B$2:$B$501,A13,BallByBall!$P$2:$P$501,B13)) -> 0 | M13: =IF(A13="","",SUMIFS(BallByBall!$W$2:$W$501,BallByBall!$B$2:$B$501,A13,BallByBall!$P$2:$P$501,B13)) -> 0 | N13: =IF(A13="","",SUMIFS(BallByBall!$X$2:$X$501,BallByBall!$B$2:$B$501,A13,BallByBall!$P$2:$P$501,B13)) -> 0 | O13: =IF(A13="","",SUMIFS(OverSummary!$G$2:$G$101,OverSummary!$A$2:$A$101,A13,OverSummary!$D$2:$D$101,B13)) -> 0 | P13: =IF(A13="","",G13*Rules!$B$13+H13*Rules!$B$14+I13*Rules!$B$15) -> 0 | Q13: =IF(A13="","",IF(G13>=100,Rules!$B$18,IF(G13>=50,Rules!$B$17,IF(G13>=30,Rules!$B$16,0)))+IF(AND(F13=1,D13<>"BWL",G13=0),Rules!$B$27,0)) -> 0 | R13: =IF(A13="","",J13*Rules!$B$19+O13*Rules!$B$22) -> 0 | S13: =IF(A13="","",IF(J13>=4,Rules!$B$21,IF(J13>=3,Rules!$B$20,0))) -> 0 | T13: =IF(A13="","",K13*Rules!$B$23+L13*Rules!$B$24+M13*Rules!$B$25+N13*Rules!$B$26) -> 0 | U13: =IF(A13="","",P13+Q13+R13+S13+T13) -> 0
... A3501: =MatchSquad!A3501 -> M070 | B3501: =MatchSquad!B3501 -> P050 | C3501: =MatchSquad!C3501 -> Kuldeep Yadav | D3501: =MatchSquad!D3501 -> BWL | E3501: =MatchSquad!E3501 -> DC | F3501: =MatchSquad!G3501 -> 0 | G3501: =IF(A3501="","",SUMIFS(BallByBall!$I$2:$I$501,BallByBall!$B$2:$B$501,A3501,BallByBall!$F$2:$F$501,B3501)) -> 0 | H3501: =IF(A3501="","",COUNTIFS(BallByBall!$B$2:$B$501,A3501,BallByBall!$F$2:$F$501,B3501,BallByBall!$Q$2:$Q$501,1)) -> 0 | I3501: =IF(A3501="","",COUNTIFS(BallByBall!$B$2:$B$501,A3501,BallByBall!$F$2:$F$501,B3501,BallByBall!$R$2:$R$501,1)) -> 0 | J3501: =IF(A3501="","",SUMIFS(BallByBall!$T$2:$T$501,BallByBall!$B$2:$B$501,A3501,BallByBall!$H$2:$H$501,B3501)) -> 0 | K3501: =IF(A3501="","",SUMIFS(BallByBall!$U$2:$U$501,BallByBall!$B$2:$B$501,A3501,BallByBall!$P$2:$P$501,B3501)) -> 0 | L3501: =IF(A3501="","",SUMIFS(BallByBall!$V$2:$V$501,BallByBall!$B$2:$B$501,A3501,BallByBall!$P$2:$P$501,B3501)) -> 0 | M3501: =IF(A3501="","",SUMIFS(BallByBall!$W$2:$W$501,BallByBall!$B$2:$B$501,A3501,BallByBall!$P$2:$P$501,B3501)) -> 0 | N3501: =IF(A3501="","",SUMIFS(BallByBall!$X$2:$X$501,BallByBall!$B$2:$B$501,A3501,BallByBall!$P$2:$P$501,B3501)) -> 0 | O3501: =IF(A3501="","",SUMIFS(OverSummary!$G$2:$G$101,OverSummary!$A$2:$A$101,A3501,OverSummary!$D$2:$D$101,B3501)) -> 0 | P3501: =IF(A3501="","",G3501*Rules!$B$13+H3501*Rules!$B$14+I3501*Rules!$B$15) -> 0 | Q3501: =IF(A3501="","",IF(G3501>=100,Rules!$B$18,IF(G3501>=50,Rules!$B$17,IF(G3501>=30,Rules!$B$16,0)))+IF(AND(F3501=1,D3501<>"BWL",G3501=0),Rules!$B$27,0)) -> 0 | R3501: =IF(A3501="","",J3501*Rules!$B$19+O3501*Rules!$B$22) -> 0 | S3501: =IF(A3501="","",IF(J3501>=4,Rules!$B$21,IF(J3501>=3,Rules!$B$20,0))) -> 0 | T3501: =IF(A3501="","",K3501*Rules!$B$23+L3501*Rules!$B$24+M3501*Rules!$B$25+N3501*Rules!$B$26) -> 0 | U3501: =IF(A3501="","",P3501+Q3501+R3501+S3501+T3501) -> 0

Sheet Validation
A1: EntryID | B1: MatchID | C1: UserName | D1: TeamName | E1: PlayersSelected | F1: UniquePlayers | G1: WK | H1: BAT | I1: AR | J1: BWL | K1: CreditsUsed | L1: CaptainCount | M1: ViceCount | N1: TeamA | O1: TeamB | P1: TeamASelected | Q1: TeamBSelected | R1: MaxFromOneTeam | S1: ValidPlayersInPool | T1: Status
A2: =Entries!A2 -> 0 | B2: =Entries!B2 -> 0 | C2: =Entries!C2 -> 0 | D2: =Entries!#REF! -> #REF! | E2: =IF(A2="","",COUNTIFS(FantasySelections!$A$2:$A$331,A2)) -> 0 | F2: =IF(A2="","",SUMIFS(FantasySelections!$P$2:$P$331,FantasySelections!$A$2:$A$331,A2)) -> 0 | G2: =IF(A2="","",COUNTIFS(FantasySelections!$A$2:$A$331,A2,FantasySelections!$G$2:$G$331,"WK")) -> 0 | H2: =IF(A2="","",COUNTIFS(FantasySelections!$A$2:$A$331,A2,FantasySelections!$G$2:$G$331,"BAT")) -> 0 | I2: =IF(A2="","",COUNTIFS(FantasySelections!$A$2:$A$331,A2,FantasySelections!$G$2:$G$331,"AR")) -> 0 | J2: =IF(A2="","",COUNTIFS(FantasySelections!$A$2:$A$331,A2,FantasySelections!$G$2:$G$331,"BWL")) -> 0 | K2: =IF(A2="","",SUMIFS(FantasySelections!$I$2:$I$331,FantasySelections!$A$2:$A$331,A2)) -> 0 | L2: =IF(A2="","",COUNTIFS(FantasySelections!$A$2:$A$331,A2,FantasySelections!$J$2:$J$331,1)) -> 0 | M2: =IF(A2="","",COUNTIFS(FantasySelections!$A$2:$A$331,A2,FantasySelections!$K$2:$K$331,1)) -> 0 | N2: =IFERROR(VLOOKUP(B2,Matches!$A$2:$E$71,4,FALSE),"") | O2: =IFERROR(VLOOKUP(B2,Matches!$A$2:$E$71,5,FALSE),"") | P2: =IF(A2="","",COUNTIFS(FantasySelections!$A$2:$A$331,A2,FantasySelections!$H$2:$H$331,N2)) -> 0 | Q2: =IF(A2="","",COUNTIFS(FantasySelections!$A$2:$A$331,A2,FantasySelections!$H$2:$H$331,O2)) -> 0 | R2: =IF(A2="","",MAX(P2,Q2)) -> 0 | S2: =IF(A2="","",SUMIFS(FantasySelections!$L$2:$L$331,FantasySelections!$A$2:$A$331,A2)) -> 0 | T2: =IF(A2="","",IF(AND(E2=Rules!$B$2,F2=Rules!$B$2,G2>=Rules!$B$3,H2>=Rules!$B$4,I2>=Rules!$B$5,J2>=Rules!$B$6,K2<=Rules!$B$8,L2=1,M2=1,R2<=Rules!$B$7,S2=Rules!$B$2),"VALID","INVALID")) -> INVALID
A3: =Entries!A3 -> 0 | B3: =Entries!B3 -> 0 | C3: =Entries!C3 -> 0 | D3: =Entries!#REF! -> #REF! | E3: =IF(A3="","",COUNTIFS(FantasySelections!$A$2:$A$331,A3)) -> 0 | F3: =IF(A3="","",SUMIFS(FantasySelections!$P$2:$P$331,FantasySelections!$A$2:$A$331,A3)) -> 0 | G3: =IF(A3="","",COUNTIFS(FantasySelections!$A$2:$A$331,A3,FantasySelections!$G$2:$G$331,"WK")) -> 0 | H3: =IF(A3="","",COUNTIFS(FantasySelections!$A$2:$A$331,A3,FantasySelections!$G$2:$G$331,"BAT")) -> 0 | I3: =IF(A3="","",COUNTIFS(FantasySelections!$A$2:$A$331,A3,FantasySelections!$G$2:$G$331,"AR")) -> 0 | J3: =IF(A3="","",COUNTIFS(FantasySelections!$A$2:$A$331,A3,FantasySelections!$G$2:$G$331,"BWL")) -> 0 | K3: =IF(A3="","",SUMIFS(FantasySelections!$I$2:$I$331,FantasySelections!$A$2:$A$331,A3)) -> 0 | L3: =IF(A3="","",COUNTIFS(FantasySelections!$A$2:$A$331,A3,FantasySelections!$J$2:$J$331,1)) -> 0 | M3: =IF(A3="","",COUNTIFS(FantasySelections!$A$2:$A$331,A3,FantasySelections!$K$2:$K$331,1)) -> 0 | N3: =IFERROR(VLOOKUP(B3,Matches!$A$2:$E$71,4,FALSE),"") | O3: =IFERROR(VLOOKUP(B3,Matches!$A$2:$E$71,5,FALSE),"") | P3: =IF(A3="","",COUNTIFS(FantasySelections!$A$2:$A$331,A3,FantasySelections!$H$2:$H$331,N3)) -> 0 | Q3: =IF(A3="","",COUNTIFS(FantasySelections!$A$2:$A$331,A3,FantasySelections!$H$2:$H$331,O3)) -> 0 | R3: =IF(A3="","",MAX(P3,Q3)) -> 0 | S3: =IF(A3="","",SUMIFS(FantasySelections!$L$2:$L$331,FantasySelections!$A$2:$A$331,A3)) -> 0 | T3: =IF(A3="","",IF(AND(E3=Rules!$B$2,F3=Rules!$B$2,G3>=Rules!$B$3,H3>=Rules!$B$4,I3>=Rules!$B$5,J3>=Rules!$B$6,K3<=Rules!$B$8,L3=1,M3=1,R3<=Rules!$B$7,S3=Rules!$B$2),"VALID","INVALID")) -> INVALID
A4: =Entries!A4 -> 0 | B4: =Entries!B4 -> 0 | C4: =Entries!C4 -> 0 | D4: =Entries!#REF! -> #REF! | E4: =IF(A4="","",COUNTIFS(FantasySelections!$A$2:$A$331,A4)) -> 0 | F4: =IF(A4="","",SUMIFS(FantasySelections!$P$2:$P$331,FantasySelections!$A$2:$A$331,A4)) -> 0 | G4: =IF(A4="","",COUNTIFS(FantasySelections!$A$2:$A$331,A4,FantasySelections!$G$2:$G$331,"WK")) -> 0 | H4: =IF(A4="","",COUNTIFS(FantasySelections!$A$2:$A$331,A4,FantasySelections!$G$2:$G$331,"BAT")) -> 0 | I4: =IF(A4="","",COUNTIFS(FantasySelections!$A$2:$A$331,A4,FantasySelections!$G$2:$G$331,"AR")) -> 0 | J4: =IF(A4="","",COUNTIFS(FantasySelections!$A$2:$A$331,A4,FantasySelections!$G$2:$G$331,"BWL")) -> 0 | K4: =IF(A4="","",SUMIFS(FantasySelections!$I$2:$I$331,FantasySelections!$A$2:$A$331,A4)) -> 0 | L4: =IF(A4="","",COUNTIFS(FantasySelections!$A$2:$A$331,A4,FantasySelections!$J$2:$J$331,1)) -> 0 | M4: =IF(A4="","",COUNTIFS(FantasySelections!$A$2:$A$331,A4,FantasySelections!$K$2:$K$331,1)) -> 0 | N4: =IFERROR(VLOOKUP(B4,Matches!$A$2:$E$71,4,FALSE),"") | O4: =IFERROR(VLOOKUP(B4,Matches!$A$2:$E$71,5,FALSE),"") | P4: =IF(A4="","",COUNTIFS(FantasySelections!$A$2:$A$331,A4,FantasySelections!$H$2:$H$331,N4)) -> 0 | Q4: =IF(A4="","",COUNTIFS(FantasySelections!$A$2:$A$331,A4,FantasySelections!$H$2:$H$331,O4)) -> 0 | R4: =IF(A4="","",MAX(P4,Q4)) -> 0 | S4: =IF(A4="","",SUMIFS(FantasySelections!$L$2:$L$331,FantasySelections!$A$2:$A$331,A4)) -> 0 | T4: =IF(A4="","",IF(AND(E4=Rules!$B$2,F4=Rules!$B$2,G4>=Rules!$B$3,H4>=Rules!$B$4,I4>=Rules!$B$5,J4>=Rules!$B$6,K4<=Rules!$B$8,L4=1,M4=1,R4<=Rules!$B$7,S4=Rules!$B$2),"VALID","INVALID")) -> INVALID
A5: =Entries!A5 -> 0 | B5: =Entries!B5 -> 0 | C5: =Entries!C5 -> 0 | D5: =Entries!#REF! -> #REF! | E5: =IF(A5="","",COUNTIFS(FantasySelections!$A$2:$A$331,A5)) -> 0 | F5: =IF(A5="","",SUMIFS(FantasySelections!$P$2:$P$331,FantasySelections!$A$2:$A$331,A5)) -> 0 | G5: =IF(A5="","",COUNTIFS(FantasySelections!$A$2:$A$331,A5,FantasySelections!$G$2:$G$331,"WK")) -> 0 | H5: =IF(A5="","",COUNTIFS(FantasySelections!$A$2:$A$331,A5,FantasySelections!$G$2:$G$331,"BAT")) -> 0 | I5: =IF(A5="","",COUNTIFS(FantasySelections!$A$2:$A$331,A5,FantasySelections!$G$2:$G$331,"AR")) -> 0 | J5: =IF(A5="","",COUNTIFS(FantasySelections!$A$2:$A$331,A5,FantasySelections!$G$2:$G$331,"BWL")) -> 0 | K5: =IF(A5="","",SUMIFS(FantasySelections!$I$2:$I$331,FantasySelections!$A$2:$A$331,A5)) -> 0 | L5: =IF(A5="","",COUNTIFS(FantasySelections!$A$2:$A$331,A5,FantasySelections!$J$2:$J$331,1)) -> 0 | M5: =IF(A5="","",COUNTIFS(FantasySelections!$A$2:$A$331,A5,FantasySelections!$K$2:$K$331,1)) -> 0 | N5: =IFERROR(VLOOKUP(B5,Matches!$A$2:$E$71,4,FALSE),"") | O5: =IFERROR(VLOOKUP(B5,Matches!$A$2:$E$71,5,FALSE),"") | P5: =IF(A5="","",COUNTIFS(FantasySelections!$A$2:$A$331,A5,FantasySelections!$H$2:$H$331,N5)) -> 0 | Q5: =IF(A5="","",COUNTIFS(FantasySelections!$A$2:$A$331,A5,FantasySelections!$H$2:$H$331,O5)) -> 0 | R5: =IF(A5="","",MAX(P5,Q5)) -> 0 | S5: =IF(A5="","",SUMIFS(FantasySelections!$L$2:$L$331,FantasySelections!$A$2:$A$331,A5)) -> 0 | T5: =IF(A5="","",IF(AND(E5=Rules!$B$2,F5=Rules!$B$2,G5>=Rules!$B$3,H5>=Rules!$B$4,I5>=Rules!$B$5,J5>=Rules!$B$6,K5<=Rules!$B$8,L5=1,M5=1,R5<=Rules!$B$7,S5=Rules!$B$2),"VALID","INVALID")) -> INVALID
A6: =Entries!A6 -> 0 | B6: =Entries!B6 -> 0 | C6: =Entries!C6 -> 0 | D6: =Entries!#REF! -> #REF! | E6: =IF(A6="","",COUNTIFS(FantasySelections!$A$2:$A$331,A6)) -> 0 | F6: =IF(A6="","",SUMIFS(FantasySelections!$P$2:$P$331,FantasySelections!$A$2:$A$331,A6)) -> 0 | G6: =IF(A6="","",COUNTIFS(FantasySelections!$A$2:$A$331,A6,FantasySelections!$G$2:$G$331,"WK")) -> 0 | H6: =IF(A6="","",COUNTIFS(FantasySelections!$A$2:$A$331,A6,FantasySelections!$G$2:$G$331,"BAT")) -> 0 | I6: =IF(A6="","",COUNTIFS(FantasySelections!$A$2:$A$331,A6,FantasySelections!$G$2:$G$331,"AR")) -> 0 | J6: =IF(A6="","",COUNTIFS(FantasySelections!$A$2:$A$331,A6,FantasySelections!$G$2:$G$331,"BWL")) -> 0 | K6: =IF(A6="","",SUMIFS(FantasySelections!$I$2:$I$331,FantasySelections!$A$2:$A$331,A6)) -> 0 | L6: =IF(A6="","",COUNTIFS(FantasySelections!$A$2:$A$331,A6,FantasySelections!$J$2:$J$331,1)) -> 0 | M6: =IF(A6="","",COUNTIFS(FantasySelections!$A$2:$A$331,A6,FantasySelections!$K$2:$K$331,1)) -> 0 | N6: =IFERROR(VLOOKUP(B6,Matches!$A$2:$E$71,4,FALSE),"") | O6: =IFERROR(VLOOKUP(B6,Matches!$A$2:$E$71,5,FALSE),"") | P6: =IF(A6="","",COUNTIFS(FantasySelections!$A$2:$A$331,A6,FantasySelections!$H$2:$H$331,N6)) -> 0 | Q6: =IF(A6="","",COUNTIFS(FantasySelections!$A$2:$A$331,A6,FantasySelections!$H$2:$H$331,O6)) -> 0 | R6: =IF(A6="","",MAX(P6,Q6)) -> 0 | S6: =IF(A6="","",SUMIFS(FantasySelections!$L$2:$L$331,FantasySelections!$A$2:$A$331,A6)) -> 0 | T6: =IF(A6="","",IF(AND(E6=Rules!$B$2,F6=Rules!$B$2,G6>=Rules!$B$3,H6>=Rules!$B$4,I6>=Rules!$B$5,J6>=Rules!$B$6,K6<=Rules!$B$8,L6=1,M6=1,R6<=Rules!$B$7,S6=Rules!$B$2),"VALID","INVALID")) -> INVALID
